Workbook

Sheet Raw_Customer_dim
A1: Customer_ID | B1: Name | C1: Age | D1: Gender | E1: City | F1: State | G1: Country | H1: Loyalty_Level
A2: CUST1000 | B2: sheena bonilla | C2: 55 | D2: Male | E2: Donaldton | F2: North Carolina | G2: USA
A3: CUST1001 | B3: Eugene Nelson | C3: 26 | D3: Female | E3: Phillipsmouth | F3: North Dakota | G3: USA | H3: Platinum
A4: CUST1002 | B4: dr. Benjamin Price | C4: 29 | D4: Female | E4: Kylebury | F4: Alabama | G4: USA | H4: Platinum
A5: CUST1003 | B5: jeremy harris | C5: 59 | D5: Female | E5: Thomastown | F5: Ohio | G5: USA | H5: Bronze
A6: CUST1004 | B6: Caroline Collins | C6: 64 | D6: Female | E6: Nicholasshire | F6: California | G6: USA | H6: Silver
A7: CUST1005 | B7: Christine Vaughn | C7: 24 | D7: Male | E7: East Amandamouth | F7: Oregon | G7: USA | H7: Bronze
A8: CUST1006 | B8: Amber Jackson | C8: 29 | D8: Female | E8: Deborahborough | F8: South Dakota | G8: USA | H8: Platinum
A9: CUST1007 | B9: Daniel Boyd | C9: 29 | D9: Female | E9: West Pamelafurt | F9: West Virginia | G9: USA | H9: Bronze
A10: CUST1008 | B10: Melissa Howard | C10: 53 | D10: Female | E10: Maynardton | F10: New Hampshire | G10: USA | H10: Gold
A11: CUST1009 | B11: Ms. Maria Leach | C11: 64 | D11: Male | E11: Melissashire | F11: Pennsylvania | G11: USA | H11: Platinum
A12: CUST1010 | B12: Dominic Page | C12: 53 | D12: Male | E12: Port Michaelburgh | F12: Pennsylvania | G12: USA | H12: Bronze
A13: CUST1011 | B13: Brian Lopez | C13: 28 | D13: Female | E13: East Krista | F13: New York | G13: USA | H13: Gold
A14: CUST1012 | B14: Kenneth Lambert | C14: 55 | D14: Female | E14: North Kathryn | F14: Kansas | G14: USA | H14: Platinum
... A19: CUST1017 | B19: Adam Cruz | C19: 60 | D19: Female | E19: Brandonville | F19: Georgia | G19: USA | H19: Platinum
A20: CUST1018 | B20: Rhonda Moss | C20: 43 | D20: Male | E20: South William | F20: Kansas | G20: USA
A21: CUST1019 | B21: Michael Torres | C21: 46 | D21: Female | E21: Gonzalezfort | F21: New Jersey | G21: USA | H21: Platinum
A22: CUST1020 | B22: Bridget Allen | C22: 59 | D22: Male | E22: Lake Shaneburgh | F22: Delaware | G22: USA | H22: Silver
A23: CUST1021 | B23: Jeff Martinez | C23: 36 | D23: Female | E23: Smithburgh | F23: Oklahoma | G23: USA | H23: Gold
A24: CUST1022 | B24: paul fox | C24: 33 | D24: Female | E24: Michaelton | F24: Hawaii | G24: USA | H24: Silver
A25: CUST1023 | B25: Jonathan Steele | C25: 52 | D25: Female | E25: Molinabury | F25: Oregon | G25: USA | H25: Silver
A26: CUST1024 | B26: Heather Collins | C26: 40 | D26: Male | E26: Rogerschester | F26: Idaho | G26: USA | H26: Platinum
A27: CUST1025 | B27: Diana Taylor | C27: 59 | D27: Female | E27: Vasqueztown | F27: California | G27: USA | H27: Bronze
A28: CUST1026 | B28: Amber Carlson | C28: 18 | D28: Female | E28: East Michellemouth | F28: Missouri | G28: USA | H28: Gold
A29: CUST1027 | B29: Leslie Johnson | C29: 31 | D29: Male | E29: Mollyshire | F29: Utah | G29: USA
A30: CUST1028 | B30: Joshua Ryan | C30: 27 | D30: Female | E30: New David | F30: New Jersey | G30: USA | H30: Platinum
A31: CUST1029 | B31: David Arnold | C31: 54 | D31: Female | E31: East Jennifer | F31: California | G31: USA | H31: Silver
A32: CUST1030 | B32: Jessica Acevedo | C32: 64 | D32: Female | E32: Amybury | F32: Pennsylvania | G32: USA | H32: Bronze
A33: CUST1031 | B33: Sarah Vance | C33: 41 | D33: Male | E33: Johnsonville | F33: Oregon | G33: USA | H33: Silver
A34: CUST1032 | B34: Mike Jennings | C34: 48 | D34: Female | E34: Fostermouth | F34: Arizona | G34: USA | H34: Gold
A35: CUST1033 | B35: Robert Jones DDS | C35: 25 | D35: Male | E35: Tristanton | F35: Oklahoma | G35: USA | H35: Platinum
A36: CUST1034 | B36: Christopher Olson | C36: 27 | D36: Female | E36: West Richard | F36: Maryland | G36: USA | H36: Platinum
A37: CUST1035 | B37: Rachel Myers | C37: 52 | D37: Male | E37: Robertberg | F37: North Dakota | G37: USA | H37: Silver
A38: CUST1036 | B38: Thomas Phillips | C38: 20 | D38: Female | E38: Luisfurt | F38: Georgia | G38: USA | H38: Gold
A39: CUST1037 | B39: Christopher Carter | C39: 27 | D39: Female | E39: Brendastad | F39: South Dakota | G39: USA
A40: CUST1038 | B40: Deanna Simpson | C40: 35 | D40: Female | E40: Brownport | F40: North Dakota | G40: USA | H40: Bronze
A41: CUST1039 | B41: Tonya Reynolds | C41: 55 | D41: Female | E41: Darleneton | F41: Michigan | G41: USA | H41: Gold
A42: CUST1040 | B42: Eric Vega | C42: 50 | D42: Male | E42: Williamsonland | F42: Kansas | G42: USA | H42: Gold
A43: CUST1041 | B43: James Gibbs | C43: 21 | D43: Male | E43: Mooneyshire | F43: Alaska | G43: USA | H43: Platinum
A44: CUST1042 | B44: William Martin | C44: 19 | D44: Male | E44: Ryanburgh | F44: Connecticut | G44: USA | H44: Platinum
...

Sheet Raw_Product_dim
A1: Product_ID | B1: Product_Name | C1: Category | D1: Sub_Category | E1: Brand | F1: Cost | G1: Stock
A2: PROD0 | B2: Brother Laser Printer | C2: Electronics | D2: Computer | E2: Hunt Inc | F2: 112.42 | G2: 416
A3: PROD1 | B3: Men's Graphic T-Shirt | C3: Clothing | D3: Tops | E3: Terry-Moore | F3: 342.56 | G3: 181
A4: PROD2 | B4: Women's Casual Hoodie | C4: Clothing | D4: Outerwear | E4: Sims Inc | G4: 352
A5: P-3 | B5: Men's Running Jacket | C5: Clothing | D5: Outerwear | E5: Pineda Ltd | F5: 364.67 | G5: 452
A6: PROD4 | B6: Women's Yoga Pants | C6: Clothing | D6: Bottoms | E6: Gonzales-Davis | F6: 306.46 | G6: 487
A7: PROD5 | B7: Men's Leather Belt | C7: Clothing | D7: Accessories | E7: Baldwin, Garza and Gonzalez | F7: 261 | G7: 59
A8: PROD6 | B8: Herbal Face Moisturizer | C8: Beauty | D8: Skincare | E8: Davidson PLC | F8: 312.8 | G8: 350
A9: PROD7 | B9: LED Table Lamp | C9: Home | D9: Lighting | E9: Harrell LLC | F9: 218.86 | G9: 170
A10: PROD8 | B10: Wireless Bluetooth Earbuds | C10: Electronics | D10: Audio | E10: Perez-Johnston | F10: 439.07 | G10: 142
A11: PROD9 | B11: Adjustable Dumbbell Set | C11: Sports | D11: Fitness | E11: Hill PLC | F11: 495.72 | G11: 323
A12: PROD10 | B12: Ceramic Kitchen Bowl Set | C12: Home | D12: Kitchen | E12: Hamilton Group | F12: 298.86 | G12: 308
A13: PROD11 | B13: HD Smart TV Stick | C13: Electronics | D13: Accessories | E13: Gibson, Hobbs and Weaver | F13: 449.4
A14: PROD12 | B14: Hair Strengthening Shampoo | C14: Beauty | D14: Haircare | E14: Rice LLC | F14: 115.82 | G14: 460
A15: PROD13 | B15: USB-C Fast Charger | C15: Electronics | D15: Accessories | E15: Dawson-Perkins | F15: 242.23 | G15: 453
A16: PROD14 | B16: Decorative Wall Mirror | C16: Home | D16: Decor | E16: Luna, Anderson and Bowman | F16: 48.01 | G16: 439
A17: PROD15 | B17: 4K Home Projector | C17: Electronics | D17: Appliances | E17: Thomas LLC | F17: 465.34 | G17: 301
A18: P-16 | B18: Beard Grooming Kit | C18: Beauty | D18: Grooming | E18: Erickson-Green | F18: 337.42 | G18: 256
A19: PROD17 | B19: Soccer Training Cone Set | C19: Sports | D19: Accessories | E19: Ford, Murphy and Wilson | F19: 144.53 | G19: 367
A20: PROD18 | B20: Women's Denim Jeans | C20: Clothing | D20: Bottoms | E20: Guerra-Hendrix | G20: 343
A21: PROD19 | B21: Knee Support Brace | C21: Sports | D21: Equipment | E21: May-Reese | F21: 21.34 | G21: 65
A22: PROD20 | B22: Outdoor Sports Water Bottle | C22: Sports | D22: Accessories | E22: Soto-Ellis | F22: 131.51
A23: PROD21 | B23: Multi-Purpose Storage Box | C23: Home | D23: Storage | E23: Gardner-Montes | F23: 123.46 | G23: 76
A24: PROD22 | B24: Carbon Fiber Tennis Racket | C24: Sports | D24: Equipment | E24: Flores, Pineda and Rodriguez | F24: 484.62 | G24: 432
A25: PROD23 | B25: Men's Formal Shirt | C25: Clothing | D25: Tops | E25: Moon, Mora and Santos | G25: 360
A26: PROD24 | B26: Foldable Camping Chair | C26: Sports | D26: Outdoor | E26: Cook Ltd | F26: 166.06 | G26: 340
A27: PROD25 | B27: Women's Scarf Set | C27: Clothing | D27: Accessories | E27: Brown and Sons | F27: 174.02 | G27: 268
A28: PROD26 | B28: Wireless Bluetooth Speaker | C28: Electronics | D28: Audio | E28: Reed-Schmidt | F28: 322.41 | G28: 213
A29: PROD27 | B29: Decorative Floor Vase | C29: Home | D29: Decor | E29: Khan, Jones and Paul | G29: 378
A30: PROD28 | B30: Sports Stopwatch Timer | C30: Sports | D30: Accessories | E30: Burns-Hansen | F30: 38.76 | G30: 137
A31: PROD29 | B31: Fabric Sofa Throw Blanket | C31: Home | D31: Decor | E31: Hoffman Group | F31: 218.48 | G31: 276
A32: PROD30 | B32: Stainless Steel Cutlery Set | C32: Home | D32: Kitchen | E32: Stevens, Fernandez and Martin | F32: 19.52 | G32: 57
A33: PROD31 | B33: Basketball | C33: Sports | D33: Team Sports | E33: Nolan-Snow | F33: 204.39 | G33: 281
A34: PROD32 | B34: Vitamin C Face Serum | C34: Beauty | D34: Skincare | E34: Griffin Ltd | F34: 283.83 | G34: 244
A35: PROD33 | B35: Modern Wall Clock | C35: Home | D35: Decor | E35: Weiss-Watson | F35: 179.77 | G35: 305
A36: PROD34 | B36: Gaming Mechanical Keyboard | C36: Electronics | D36: Computer | E36: Lucero LLC | F36: 419.28 | G36: 86
A37: PROD35 | B37: Bedroom Table Lamp | C37: Home | D37: Lighting | E37: Jones LLC | F37: 382.22 | G37: 329
A38: PROD36 | B38: Women's Summer Dress | C38: Clothing | D38: Tops | E38: Smith-Mills | F38: 223.43 | G38: 154
A39: PROD37 | B39: Men's Casual Sneakers | C39: Clothing | D39: Footwear | E39: Hogan-Lee | F39: 353.47 | G39: 214
A40: PROD38 | B40: Sports Water Hydration Pack | C40: Sports | D40: Outdoor | E40: Sims-Smith | F40: 135.61 | G40: 394
...

Sheet Raw_Store_dim
A1: Store_ID | B1: Store_Name | C1: Region | D1: City | E1: Store_Type
A2: STORE0 | B2: Rivera-Warner | C2: East | D2: Washingtonfurt | E2: Flagship
A3: STORE1 | B3: Martinez, Adkins and Johnson | C3: North | D3: Danielmouth | E3: Flagship
A4: STORE2 | B4: Black-Horn | C4: South | D4: North Nancyview | E4: Outlet
A5: STORE3 | B5: Johnson-Wright | C5: North | D5: Hoodberg | E5: Outlet
A6: STORE4 | B6: Alexander Group | C6: South | D6: Port Sharon | E6: Online
A7: STORE5 | B7: Gray Ltd | C7: North | D7: New Michaelchester | E7: Outlet
A8: STORE6 | B8: Benson-Elliott | C8: East | D8: Port Josephberg | E8: Online
A9: STORE7 | B9: Martinez-Mullins | C9: South | D9: Williamsfurt | E9: Online
A10: STORE8 | B10: Bean, Jones and Park | C10: West | D10: Thompsonborough | E10: Online
A11: STORE9 | B11: Moore, Padilla and Butler | C11: South | D11: East Johnstad | E11: Flagship
A12: STORE10 | B12: Hill, Wagner and Ballard | C12: East | D12: East Davidville | E12: Online
... A21: STORE19 | B21: Mann-Austin | C21: East | D21: Vasquezborough | E21: Online

Sheet Raw_SalesFact
A1: Sales_ID | B1: Order_Date | C1: Customer_ID | D1: Product_ID | E1: Store_ID | F1: Quantity | G1: Unit_Price | H1: Discount | I1: Payment_Type | J1: Total_Amount
A2: SALE0 | B2: 45480 | C2: CUST1409 | D2: PROD97 | E2: STORE3 | F2: 1 | G2: 218.04 | H2: 0.09 | I2: Credit Card | J2: 198.4164
A3: SALE1 | B3: 45285 | C3: CUST1467 | D3: PROD74 | E3: STORE17 | F3: 3 | G3: 104.47 | H3: 0.27 | I3: PayPal | J3: 228.7893
A4: SALE2 | B4: 45446 | C4: CUST1056 | D4: PROD49 | E4: STORE8 | F4: 4 | G4: 914.05 | H4: 0.25 | I4: Credit Card | J4: 2742.15
A5: SALE3 | B5: 45259 | C5: CUST1346 | D5: PROD76 | E5: STORE8 | F5: 1 | G5: 921.51 | H5: 0.16 | I5: COD | J5: 774.0684
A6: SALE4 | B6: 45297 | C6: CUST1493 | D6: PROD59 | E6: STORE5 | F6: 3 | G6: 745.3 | H6: 0.18 | I6: Credit Card | J6: 1833.438
A7: SALE5 | B7: 45499 | C7: CUST1116 | D7: PROD15 | E7: STORE7 | F7: 3 | G7: 147.01 | H7: 0.19 | I7: COD | J7: 357.2343
A8: SALE6 | B8: 45850 | C8: CUST1016 | D8: PROD56 | E8: STORE4 | F8: 2 | G8: 785.31 | H8: 0.15 | I8: PayPal | J8: 1335.027
A9: SALE7 | B9: 45248 | C9: CUST1152 | D9: PROD70 | E9: STORE8 | F9: 4 | G9: 342.39 | H9: 0.23 | I9: PayPal | J9: 1054.5612
A10: SALE8 | B10: 45781 | C10: CUST1187 | D10: PROD99 | E10: STORE5 | G10: 448.25 | H10: 0.07 | I10: PayPal | J10: 1250.6175
A11: SALE9 | B11: 45869 | C11: CUST1464 | D11: PROD33 | E11: STORE0 | F11: 2 | G11: 873.17 | H11: 0.23 | I11: PayPal | J11: 1344.6818
A12: SALE10 | B12: 45335 | C12: CUST1065 | D12: PROD24 | E12: STORE14 | F12: 1 | G12: 278.63 | H12: 0.07 | I12: Credit Card | J12: 259.1259
A13: SALE11 | B13: 45801 | C13: CUST1320 | D13: PROD39 | E13: STORE1 | F13: 4 | G13: 286.92 | H13: 0.17 | I13: Credit Card | J13: 952.5744
A14: SALE12 | B14: 45528 | C14: CUST1237 | D14: PROD88 | E14: STORE4 | F14: 4 | G14: 644.58 | H14: 0.01 | I14: Credit Card | J14: 2552.5368
A15: SALE13 | B15: 45875 | C15: CUST1443 | D15: PROD34 | E15: STORE16 | F15: 2 | G15: 316.9 | H15: 0.3 | I15: PayPal | J15: 443.66
A16: SALE14 | B16: 45829 | C16: CUST1348 | D16: PROD24 | E16: STORE15 | F16: 4 | G16: 403.47 | H16: 0.29 | I16: PayPal | J16: 1145.8548
A17: SALE15 | B17: 45636 | C17: CUST1435 | D17: PROD36 | E17: STORE9 | G17: 871.34 | H17: 0.04 | I17: COD | J17: 2509.4592
A18: SALE16 | B18: 45913 | C18: CUST1276 | D18: PROD65 | E18: STORE19 | F18: 2 | G18: 451.98 | H18: 0.25 | I18: Credit Card | J18: 677.97
A19: SALE17 | B19: 45637 | C19: CUST1079 | D19: PROD27 | E19: STORE4 | F19: 2 | G19: 502.69 | H19: 0.23 | I19: Credit Card | J19: 774.1426
A20: SALE18 | B20: 45517 | C20: CUST1094 | D20: PROD39 | E20: STORE4 | F20: 2 | G20: 559.23 | H20: 0.25 | I20: COD | J20: 838.845
A21: SALE19 | B21: 45369 | C21: CUST1239 | D21: PROD60 | E21: STORE13 | F21: 4 | H21: 0.04 | I21: COD | J21: 1782.4512
A22: SALE20 | B22: 45843 | C22: CUST1144 | D22: PROD72 | E22: STORE17 | F22: 3 | G22: 986.04 | H22: 0.27 | I22: COD | J22: 2159.4276
A23: SALE21 | B23: 45447 | C23: CUST1396 | D23: PROD43 | E23: STORE18 | F23: 1 | G23: 589.56 | H23: 0.22 | I23: Credit Card | J23: 459.8568
A24: SALE22 | B24: 45394 | C24: CUST1476 | D24: PROD69 | E24: STORE10 | F24: 3 | G24: 979.42 | H24: 0.03 | I24: PayPal | J24: 2850.1122
A25: SALE23 | B25: 45466 | C25: CUST1368 | D25: PROD12 | E25: STORE8 | F25: 1 | G25: 719.28 | H25: 0.08 | I25: Credit Card | J25: 661.7376
A26: SALE24 | B26: 45908 | C26: CUST1186 | D26: PROD67 | E26: STORE6 | F26: 3 | G26: 77.6 | H26: 0.07 | I26: Credit Card | J26: 216.504
A27: SALE25 | B27: 45552 | C27: CUST1381 | D27: PROD5 | E27: STORE3 | F27: 4 | G27: 852.71 | H27: 0.14 | I27: PayPal | J27: 2933.3224
A28: SALE26 | B28: 45294 | C28: CUST1213 | D28: PROD98 | E28: STORE8 | F28: 4 | G28: 156.16 | I28: Credit Card | J28: 599.6544
A29: SALE27 | B29: 45710 | C29: CUST1200 | D29: PROD77 | E29: STORE8 | F29: 3 | G29: 815.49 | H29: 0.17 | I29: Credit Card | J29: 2030.5701
A30: SALE28 | B30: 45923 | C30: CUST1148 | D30: PROD13 | E30: STORE2 | F30: 2 | G30: 74.21 | H30: 0.11 | I30: PayPal | J30: 132.0938
A31: SALE29 | B31: 45302 | C31: CUST1348 | D31: PROD99 | E31: STORE3 | G31: 451.67 | H31: 0.15 | I31: Credit Card | J31: 1535.678
A32: SALE30 | B32: 45217 | C32: CUST1028 | D32: PROD5 | E32: STORE19 | F32: 1 | G32: 429.38 | H32: 0.13 | I32: PayPal | J32: 373.5606
A33: SALE31 | B33: 45593 | C33: CUST1412 | D33: PROD53 | E33: STORE12 | F33: 2 | G33: 148.96 | H33: 0.03 | I33: COD | J33: 288.9824
A34: SALE32 | B34: 45597 | C34: CUST1398 | D34: PROD75 | E34: STORE8 | F34: 4 | G34: 313.83 | H34: 0.08 | I34: Credit Card | J34: 1154.8944
A35: SALE33 | B35: 45620 | C35: CUST1453 | D35: PROD12 | E35: STORE6 | F35: 2 | G35: 717.31 | H35: 0.15 | I35: Credit Card | J35: 1219.427
A36: SALE34 | B36: 45215 | C36: CUST1344 | D36: PROD79 | E36: STORE1 | G36: 873.22 | H36: 0.18 | I36: Credit Card | J36: 2148.1212
A37: SALE35 | B37: 45878 | C37: CUST1218 | D37: PROD16 | E37: STORE3 | F37: 4 | G37: 109.36 | H37: 0.19 | I37: COD | J37: 354.3264
A38: SALE36 | B38: 45635 | C38: CUST1086 | D38: PROD5 | E38: STORE7 | F38: 3 | G38: 559.52 | H38: 0.16 | I38: PayPal | J38: 1409.9904
A39: SALE37 | B39: 45329 | C39: CUST1492 | D39: PROD10 | E39: STORE17 | F39: 3 | G39: 121.76 | H39: 0.27 | I39: PayPal | J39: 266.6544
A40: SALE38 | B40: 45378 | C40: CUST1189 | D40: PROD33 | E40: STORE13 | F40: 4 | G40: 735.32 | H40: 0.06 | I40: COD | J40: 2764.8032
...

Sheet Cleaned_CustomerTable
A1: Customer_ID | B1: Name | C1: Age | D1: Gender | E1: City | F1: State | G1: Country | H1: Loyalty_Level | I1: Duplicate_Check
A2: =IF(LEFT(Raw_Customer_dim!A2,2)="C-","CUST"&MID(Raw_Customer_dim!A2,3,10),Raw_Customer_dim!A2) -> CUST1000 | B2: =PROPER(TRIM(Raw_Customer_dim!B2)) -> Sheena Bonilla | C2: =Raw_Customer_dim!C2 -> 55 | D2: =Raw_Customer_dim!D2 -> Male | E2: =TRIM(Raw_Customer_dim!E2) -> Donaldton | F2: =TRIM(Raw_Customer_dim!F2) -> North Carolina | G2: =TRIM(Raw_Customer_dim!G2) -> USA | H2: =IF(Raw_Customer_dim!H2="","Standard",Raw_Customer_dim!H2) -> Standard | I2: =IF(COUNTIF($A$2:$A2,A2)>1,"Duplicate","Unique") -> Unique
A3: =IF(LEFT(Raw_Customer_dim!A3,2)="C-","CUST"&MID(Raw_Customer_dim!A3,3,10),Raw_Customer_dim!A3) -> CUST1001 | B3: =PROPER(TRIM(Raw_Customer_dim!B3)) -> Eugene Nelson | C3: =Raw_Customer_dim!C3 -> 26 | D3: =Raw_Customer_dim!D3 -> Female | E3: =TRIM(Raw_Customer_dim!E3) -> Phillipsmouth | F3: =TRIM(Raw_Customer_dim!F3) -> North Dakota | G3: =TRIM(Raw_Customer_dim!G3) -> USA | H3: =IF(Raw_Customer_dim!H3="","Standard",Raw_Customer_dim!H3) -> Platinum | I3: =IF(COUNTIF($A$2:$A3,A3)>1,"Duplicate","Unique") -> Unique
A4: =IF(LEFT(Raw_Customer_dim!A4,2)="C-","CUST"&MID(Raw_Customer_dim!A4,3,10),Raw_Customer_dim!A4) -> CUST1002 | B4: =PROPER(TRIM(Raw_Customer_dim!B4)) -> Dr. Benjamin Price | C4: =Raw_Customer_dim!C4 -> 29 | D4: =Raw_Customer_dim!D4 -> Female | E4: =TRIM(Raw_Customer_dim!E4) -> Kylebury | F4: =TRIM(Raw_Customer_dim!F4) -> Alabama | G4: =TRIM(Raw_Customer_dim!G4) -> USA | H4: =IF(Raw_Customer_dim!H4="","Standard",Raw_Customer_dim!H4) -> Platinum | I4: =IF(COUNTIF($A$2:$A4,A4)>1,"Duplicate","Unique") -> Unique
A5: =IF(LEFT(Raw_Customer_dim!A5,2)="C-","CUST"&MID(Raw_Customer_dim!A5,3,10),Raw_Customer_dim!A5) -> CUST1003 | B5: =PROPER(TRIM(Raw_Customer_dim!B5)) -> Jeremy Harris | C5: =Raw_Customer_dim!C5 -> 59 | D5: =Raw_Customer_dim!D5 -> Female | E5: =TRIM(Raw_Customer_dim!E5) -> Thomastown | F5: =TRIM(Raw_Customer_dim!F5) -> Ohio | G5: =TRIM(Raw_Customer_dim!G5) -> USA | H5: =IF(Raw_Customer_dim!H5="","Standard",Raw_Customer_dim!H5) -> Bronze | I5: =IF(COUNTIF($A$2:$A5,A5)>1,"Duplicate","Unique") -> Unique
A6: =IF(LEFT(Raw_Customer_dim!A6,2)="C-","CUST"&MID(Raw_Customer_dim!A6,3,10),Raw_Customer_dim!A6) -> CUST1004 | B6: =PROPER(TRIM(Raw_Customer_dim!B6)) -> Caroline Collins | C6: =Raw_Customer_dim!C6 -> 64 | D6: =Raw_Customer_dim!D6 -> Female | E6: =TRIM(Raw_Customer_dim!E6) -> Nicholasshire | F6: =TRIM(Raw_Customer_dim!F6) -> California | G6: =TRIM(Raw_Customer_dim!G6) -> USA | H6: =IF(Raw_Customer_dim!H6="","Standard",Raw_Customer_dim!H6) -> Silver | I6: =IF(COUNTIF($A$2:$A6,A6)>1,"Duplicate","Unique") -> Unique
A7: =IF(LEFT(Raw_Customer_dim!A7,2)="C-","CUST"&MID(Raw_Customer_dim!A7,3,10),Raw_Customer_dim!A7) -> CUST1005 | B7: =PROPER(TRIM(Raw_Customer_dim!B7)) -> Christine Vaughn | C7: =Raw_Customer_dim!C7 -> 24 | D7: =Raw_Customer_dim!D7 -> Male | E7: =TRIM(Raw_Customer_dim!E7) -> East Amandamouth | F7: =TRIM(Raw_Customer_dim!F7) -> Oregon | G7: =TRIM(Raw_Customer_dim!G7) -> USA | H7: =IF(Raw_Customer_dim!H7="","Standard",Raw_Customer_dim!H7) -> Bronze | I7: =IF(COUNTIF($A$2:$A7,A7)>1,"Duplicate","Unique") -> Unique
A8: =IF(LEFT(Raw_Customer_dim!A8,2)="C-","CUST"&MID(Raw_Customer_dim!A8,3,10),Raw_Customer_dim!A8) -> CUST1006 | B8: =PROPER(TRIM(Raw_Customer_dim!B8)) -> Amber Jackson | C8: =Raw_Customer_dim!C8 -> 29 | D8: =Raw_Customer_dim!D8 -> Female | E8: =TRIM(Raw_Customer_dim!E8) -> Deborahborough | F8: =TRIM(Raw_Customer_dim!F8) -> South Dakota | G8: =TRIM(Raw_Customer_dim!G8) -> USA | H8: =IF(Raw_Customer_dim!H8="","Standard",Raw_Customer_dim!H8) -> Platinum | I8: =IF(COUNTIF($A$2:$A8,A8)>1,"Duplicate","Unique") -> Unique
A9: =IF(LEFT(Raw_Customer_dim!A9,2)="C-","CUST"&MID(Raw_Customer_dim!A9,3,10),Raw_Customer_dim!A9) -> CUST1007 | B9: =PROPER(TRIM(Raw_Customer_dim!B9)) -> Daniel Boyd | C9: =Raw_Customer_dim!C9 -> 29 | D9: =Raw_Customer_dim!D9 -> Female | E9: =TRIM(Raw_Customer_dim!E9) -> West Pamelafurt | F9: =TRIM(Raw_Customer_dim!F9) -> West Virginia | G9: =TRIM(Raw_Customer_dim!G9) -> USA | H9: =IF(Raw_Customer_dim!H9="","Standard",Raw_Customer_dim!H9) -> Bronze | I9: =IF(COUNTIF($A$2:$A9,A9)>1,"Duplicate","Unique") -> Unique
A10: =IF(LEFT(Raw_Customer_dim!A10,2)="C-","CUST"&MID(Raw_Customer_dim!A10,3,10),Raw_Customer_dim!A10) -> CUST1008 | B10: =PROPER(TRIM(Raw_Customer_dim!B10)) -> Melissa Howard | C10: =Raw_Customer_dim!C10 -> 53 | D10: =Raw_Customer_dim!D10 -> Female | E10: =TRIM(Raw_Customer_dim!E10) -> Maynardton | F10: =TRIM(Raw_Customer_dim!F10) -> New Hampshire | G10: =TRIM(Raw_Customer_dim!G10) -> USA | H10: =IF(Raw_Customer_dim!H10="","Standard",Raw_Customer_dim!H10) -> Gold | I10: =IF(COUNTIF($A$2:$A10,A10)>1,"Duplicate","Unique") -> Unique
A11: =IF(LEFT(Raw_Customer_dim!A11,2)="C-","CUST"&MID(Raw_Customer_dim!A11,3,10),Raw_Customer_dim!A11) -> CUST1009 | B11: =PROPER(TRIM(Raw_Customer_dim!B11)) -> Ms. Maria Leach | C11: =Raw_Customer_dim!C11 -> 64 | D11: =Raw_Customer_dim!D11 -> Male | E11: =TRIM(Raw_Customer_dim!E11) -> Melissashire | F11: =TRIM(Raw_Customer_dim!F11) -> Pennsylvania | G11: =TRIM(Raw_Customer_dim!G11) -> USA | H11: =IF(Raw_Customer_dim!H11="","Standard",Raw_Customer_dim!H11) -> Platinum | I11: =IF(COUNTIF($A$2:$A11,A11)>1,"Duplicate","Unique") -> Unique
A12: =IF(LEFT(Raw_Customer_dim!A12,2)="C-","CUST"&MID(Raw_Customer_dim!A12,3,10),Raw_Customer_dim!A12) -> CUST1010 | B12: =PROPER(TRIM(Raw_Customer_dim!B12)) -> Dominic Page | C12: =Raw_Customer_dim!C12 -> 53 | D12: =Raw_Customer_dim!D12 -> Male | E12: =TRIM(Raw_Customer_dim!E12) -> Port Michaelburgh | F12: =TRIM(Raw_Customer_dim!F12) -> Pennsylvania | G12: =TRIM(Raw_Customer_dim!G12) -> USA | H12: =IF(Raw_Customer_dim!H12="","Standard",Raw_Customer_dim!H12) -> Bronze | I12: =IF(COUNTIF($A$2:$A12,A12)>1,"Duplicate","Unique") -> Unique
A13: =IF(LEFT(Raw_Customer_dim!A13,2)="C-","CUST"&MID(Raw_Customer_dim!A13,3,10),Raw_Customer_dim!A13) -> CUST1011 | B13: =PROPER(TRIM(Raw_Customer_dim!B13)) -> Brian Lopez | C13: =Raw_Customer_dim!C13 -> 28 | D13: =Raw_Customer_dim!D13 -> Female | E13: =TRIM(Raw_Customer_dim!E13) -> East Krista | F13: =TRIM(Raw_Customer_dim!F13) -> New York | G13: =TRIM(Raw_Customer_dim!G13) -> USA | H13: =IF(Raw_Customer_dim!H13="","Standard",Raw_Customer_dim!H13) -> Gold | I13: =IF(COUNTIF($A$2:$A13,A13)>1,"Duplicate","Unique") -> Unique
... A501: =IF(LEFT(Raw_Customer_dim!A501,2)="C-","CUST"&MID(Raw_Customer_dim!A501,3,10),Raw_Customer_dim!A501) -> CUST1499 | B501: =PROPER(TRIM(Raw_Customer_dim!B501)) -> Philip Pennington | C501: =Raw_Customer_dim!C501 -> 27 | D501: =Raw_Customer_dim!D501 -> Female | E501: =TRIM(Raw_Customer_dim!E501) -> East Valerieview | F501: =TRIM(Raw_Customer_dim!F501) -> Oregon | G501: =TRIM(Raw_Customer_dim!G501) -> USA | H501: =IF(Raw_Customer_dim!H501="","Standard",Raw_Customer_dim!H501) -> Platinum | I501: =IF(COUNTIF($A$2:$A501,A501)>1,"Duplicate","Unique") -> Unique
A503: Cleaning notes / assumptions:
A504: - Customer_ID: 4 IDs used an inconsistent 'C-1464' style format instead of 'CUST1464'; corrected to the standard format so they match Sales_Fact.
A505: - Name: extra spaces trimmed and consistent title case applied with PROPER().
A506: - Loyalty_Level: 4 blank records recoded as 'Standard' (customer not yet enrolled in a loyalty tier).
A507: - Duplicate_Check: COUNTIF-based flag confirms no duplicate Customer_ID records (all 'Unique').

Sheet Cleaned_ProductTable
A1: Product_ID | B1: Product_Name | C1: Category | D1: Brand | E1: Cost | F1: Stock | G1: Duplicate_Check
A2: =IF(LEFT(Raw_Product_dim!A2,2)="P-","PROD"&MID(Raw_Product_dim!A2,3,10),Raw_Product_dim!A2) -> PROD0 | B2: =TRIM(Raw_Product_dim!B2) -> Brother Laser Printer | C2: =Raw_Product_dim!C2 -> Electronics | D2: =TRIM(Raw_Product_dim!E2) -> Hunt Inc | E2: =IF(Raw_Product_dim!F2="",ROUND(AVERAGEIF(Raw_Product_dim!$C$2:$C$101,C2,Raw_Product_dim!$F$2:$F$101),2),Raw_Product_dim!F2) -> 112.42 | F2: =IF(Raw_Product_dim!G2="",ROUND(AVERAGEIF(Raw_Product_dim!$C$2:$C$101,C2,Raw_Product_dim!$G$2:$G$101),0),Raw_Product_dim!G2) -> 416 | G2: =IF(COUNTIF($A$2:$A2,A2)>1,"Duplicate","Unique") -> Unique
A3: =IF(LEFT(Raw_Product_dim!A3,2)="P-","PROD"&MID(Raw_Product_dim!A3,3,10),Raw_Product_dim!A3) -> PROD1 | B3: =TRIM(Raw_Product_dim!B3) -> Men's Graphic T-Shirt | C3: =Raw_Product_dim!C3 -> Clothing | D3: =TRIM(Raw_Product_dim!E3) -> Terry-Moore | E3: =IF(Raw_Product_dim!F3="",ROUND(AVERAGEIF(Raw_Product_dim!$C$2:$C$101,C3,Raw_Product_dim!$F$2:$F$101),2),Raw_Product_dim!F3) -> 342.56 | F3: =IF(Raw_Product_dim!G3="",ROUND(AVERAGEIF(Raw_Product_dim!$C$2:$C$101,C3,Raw_Product_dim!$G$2:$G$101),0),Raw_Product_dim!G3) -> 181 | G3: =IF(COUNTIF($A$2:$A3,A3)>1,"Duplicate","Unique") -> Unique
A4: =IF(LEFT(Raw_Product_dim!A4,2)="P-","PROD"&MID(Raw_Product_dim!A4,3,10),Raw_Product_dim!A4) -> PROD2 | B4: =TRIM(Raw_Product_dim!B4) -> Women's Casual Hoodie | C4: =Raw_Product_dim!C4 -> Clothing | D4: =TRIM(Raw_Product_dim!E4) -> Sims Inc | E4: =IF(Raw_Product_dim!F4="",ROUND(AVERAGEIF(Raw_Product_dim!$C$2:$C$101,C4,Raw_Product_dim!$F$2:$F$101),2),Raw_Product_dim!F4) -> 265.73 | F4: =IF(Raw_Product_dim!G4="",ROUND(AVERAGEIF(Raw_Product_dim!$C$2:$C$101,C4,Raw_Product_dim!$G$2:$G$101),0),Raw_Product_dim!G4) -> 352 | G4: =IF(COUNTIF($A$2:$A4,A4)>1,"Duplicate","Unique") -> Unique
A5: =IF(LEFT(Raw_Product_dim!A5,2)="P-","PROD"&MID(Raw_Product_dim!A5,3,10),Raw_Product_dim!A5) -> PROD3 | B5: =TRIM(Raw_Product_dim!B5) -> Men's Running Jacket | C5: =Raw_Product_dim!C5 -> Clothing | D5: =TRIM(Raw_Product_dim!E5) -> Pineda Ltd | E5: =IF(Raw_Product_dim!F5="",ROUND(AVERAGEIF(Raw_Product_dim!$C$2:$C$101,C5,Raw_Product_dim!$F$2:$F$101),2),Raw_Product_dim!F5) -> 364.67 | F5: =IF(Raw_Product_dim!G5="",ROUND(AVERAGEIF(Raw_Product_dim!$C$2:$C$101,C5,Raw_Product_dim!$G$2:$G$101),0),Raw_Product_dim!G5) -> 452 | G5: =IF(COUNTIF($A$2:$A5,A5)>1,"Duplicate","Unique") -> Unique
A6: =IF(LEFT(Raw_Product_dim!A6,2)="P-","PROD"&MID(Raw_Product_dim!A6,3,10),Raw_Product_dim!A6) -> PROD4 | B6: =TRIM(Raw_Product_dim!B6) -> Women's Yoga Pants | C6: =Raw_Product_dim!C6 -> Clothing | D6: =TRIM(Raw_Product_dim!E6) -> Gonzales-Davis | E6: =IF(Raw_Product_dim!F6="",ROUND(AVERAGEIF(Raw_Product_dim!$C$2:$C$101,C6,Raw_Product_dim!$F$2:$F$101),2),Raw_Product_dim!F6) -> 306.46 | F6: =IF(Raw_Product_dim!G6="",ROUND(AVERAGEIF(Raw_Product_dim!$C$2:$C$101,C6,Raw_Product_dim!$G$2:$G$101),0),Raw_Product_dim!G6) -> 487 | G6: =IF(COUNTIF($A$2:$A6,A6)>1,"Duplicate","Unique") -> Unique
A7: =IF(LEFT(Raw_Product_dim!A7,2)="P-","PROD"&MID(Raw_Product_dim!A7,3,10),Raw_Product_dim!A7) -> PROD5 | B7: =TRIM(Raw_Product_dim!B7) -> Men's Leather Belt | C7: =Raw_Product_dim!C7 -> Clothing | D7: =TRIM(Raw_Product_dim!E7) -> Baldwin, Garza and Gonzalez | E7: =IF(Raw_Product_dim!F7="",ROUND(AVERAGEIF(Raw_Product_dim!$C$2:$C$101,C7,Raw_Product_dim!$F$2:$F$101),2),Raw_Product_dim!F7) -> 261 | F7: =IF(Raw_Product_dim!G7="",ROUND(AVERAGEIF(Raw_Product_dim!$C$2:$C$101,C7,Raw_Product_dim!$G$2:$G$101),0),Raw_Product_dim!G7) -> 59 | G7: =IF(COUNTIF($A$2:$A7,A7)>1,"Duplicate","Unique") -> Unique
A8: =IF(LEFT(Raw_Product_dim!A8,2)="P-","PROD"&MID(Raw_Product_dim!A8,3,10),Raw_Product_dim!A8) -> PROD6 | B8: =TRIM(Raw_Product_dim!B8) -> Herbal Face Moisturizer | C8: =Raw_Product_dim!C8 -> Beauty | D8: =TRIM(Raw_Product_dim!E8) -> Davidson PLC | E8: =IF(Raw_Product_dim!F8="",ROUND(AVERAGEIF(Raw_Product_dim!$C$2:$C$101,C8,Raw_Product_dim!$F$2:$F$101),2),Raw_Product_dim!F8) -> 312.8 | F8: =IF(Raw_Product_dim!G8="",ROUND(AVERAGEIF(Raw_Product_dim!$C$2:$C$101,C8,Raw_Product_dim!$G$2:$G$101),0),Raw_Product_dim!G8) -> 350 | G8: =IF(COUNTIF($A$2:$A8,A8)>1,"Duplicate","Unique") -> Unique
A9: =IF(LEFT(Raw_Product_dim!A9,2)="P-","PROD"&MID(Raw_Product_dim!A9,3,10),Raw_Product_dim!A9) -> PROD7 | B9: =TRIM(Raw_Product_dim!B9) -> LED Table Lamp | C9: =Raw_Product_dim!C9 -> Home | D9: =TRIM(Raw_Product_dim!E9) -> Harrell LLC | E9: =IF(Raw_Product_dim!F9="",ROUND(AVERAGEIF(Raw_Product_dim!$C$2:$C$101,C9,Raw_Product_dim!$F$2:$F$101),2),Raw_Product_dim!F9) -> 218.86 | F9: =IF(Raw_Product_dim!G9="",ROUND(AVERAGEIF(Raw_Product_dim!$C$2:$C$101,C9,Raw_Product_dim!$G$2:$G$101),0),Raw_Product_dim!G9) -> 170 | G9: =IF(COUNTIF($A$2:$A9,A9)>1,"Duplicate","Unique") -> Unique
A10: =IF(LEFT(Raw_Product_dim!A10,2)="P-","PROD"&MID(Raw_Product_dim!A10,3,10),Raw_Product_dim!A10) -> PROD8 | B10: =TRIM(Raw_Product_dim!B10) -> Wireless Bluetooth Earbuds | C10: =Raw_Product_dim!C10 -> Electronics | D10: =TRIM(Raw_Product_dim!E10) -> Perez-Johnston | E10: =IF(Raw_Product_dim!F10="",ROUND(AVERAGEIF(Raw_Product_dim!$C$2:$C$101,C10,Raw_Product_dim!$F$2:$F$101),2),Raw_Product_dim!F10) -> 439.07 | F10: =IF(Raw_Product_dim!G10="",ROUND(AVERAGEIF(Raw_Product_dim!$C$2:$C$101,C10,Raw_Product_dim!$G$2:$G$101),0),Raw_Product_dim!G10) -> 142 | G10: =IF(COUNTIF($A$2:$A10,A10)>1,"Duplicate","Unique") -> Unique
A11: =IF(LEFT(Raw_Product_dim!A11,2)="P-","PROD"&MID(Raw_Product_dim!A11,3,10),Raw_Product_dim!A11) -> PROD9 | B11: =TRIM(Raw_Product_dim!B11) -> Adjustable Dumbbell Set | C11: =Raw_Product_dim!C11 -> Sports | D11: =TRIM(Raw_Product_dim!E11) -> Hill PLC | E11: =IF(Raw_Product_dim!F11="",ROUND(AVERAGEIF(Raw_Product_dim!$C$2:$C$101,C11,Raw_Product_dim!$F$2:$F$101),2),Raw_Product_dim!F11) -> 495.72 | F11: =IF(Raw_Product_dim!G11="",ROUND(AVERAGEIF(Raw_Product_dim!$C$2:$C$101,C11,Raw_Product_dim!$G$2:$G$101),0),Raw_Product_dim!G11) -> 323 | G11: =IF(COUNTIF($A$2:$A11,A11)>1,"Duplicate","Unique") -> Unique
A12: =IF(LEFT(Raw_Product_dim!A12,2)="P-","PROD"&MID(Raw_Product_dim!A12,3,10),Raw_Product_dim!A12) -> PROD10 | B12: =TRIM(Raw_Product_dim!B12) -> Ceramic Kitchen Bowl Set | C12: =Raw_Product_dim!C12 -> Home | D12: =TRIM(Raw_Product_dim!E12) -> Hamilton Group | E12: =IF(Raw_Product_dim!F12="",ROUND(AVERAGEIF(Raw_Product_dim!$C$2:$C$101,C12,Raw_Product_dim!$F$2:$F$101),2),Raw_Product_dim!F12) -> 298.86 | F12: =IF(Raw_Product_dim!G12="",ROUND(AVERAGEIF(Raw_Product_dim!$C$2:$C$101,C12,Raw_Product_dim!$G$2:$G$101),0),Raw_Product_dim!G12) -> 308 | G12: =IF(COUNTIF($A$2:$A12,A12)>1,"Duplicate","Unique") -> Unique
A13: =IF(LEFT(Raw_Product_dim!A13,2)="P-","PROD"&MID(Raw_Product_dim!A13,3,10),Raw_Product_dim!A13) -> PROD11 | B13: =TRIM(Raw_Product_dim!B13) -> HD Smart TV Stick | C13: =Raw_Product_dim!C13 -> Electronics | D13: =TRIM(Raw_Product_dim!E13) -> Gibson, Hobbs and Weaver | E13: =IF(Raw_Product_dim!F13="",ROUND(AVERAGEIF(Raw_Product_dim!$C$2:$C$101,C13,Raw_Product_dim!$F$2:$F$101),2),Raw_Product_dim!F13) -> 449.4 | F13: =IF(Raw_Product_dim!G13="",ROUND(AVERAGEIF(Raw_Product_dim!$C$2:$C$101,C13,Raw_Product_dim!$G$2:$G$101),0),Raw_Product_dim!G13) -> 275 | G13: =IF(COUNTIF($A$2:$A13,A13)>1,"Duplicate","Unique") -> Unique
... A101: =IF(LEFT(Raw_Product_dim!A101,2)="P-","PROD"&MID(Raw_Product_dim!A101,3,10),Raw_Product_dim!A101) -> PROD99 | B101: =TRIM(Raw_Product_dim!B101) -> Stainless Steel Cookware Set | C101: =Raw_Product_dim!C101 -> Home | D101: =TRIM(Raw_Product_dim!E101) -> Campbell Ltd | E101: =IF(Raw_Product_dim!F101="",ROUND(AVERAGEIF(Raw_Product_dim!$C$2:$C$101,C101,Raw_Product_dim!$F$2:$F$101),2),Raw_Product_dim!F101) -> 201.41 | F101: =IF(Raw_Product_dim!G101="",ROUND(AVERAGEIF(Raw_Product_dim!$C$2:$C$101,C101,Raw_Product_dim!$G$2:$G$101),0),Raw_Product_dim!G101) -> 146 | G101: =IF(COUNTIF($A$2:$A101,A101)>1,"Duplicate","Unique") -> Unique
A103: Cleaning notes / assumptions:
A104: - Product_ID: 2 IDs used an inconsistent 'P-3' style format instead of 'PROD3'; corrected to the standard format so they match Sales_Fact.
A105: - Sub_Category column removed (identified as irrelevant per assignment brief).
A106: - Cost: 6 missing values imputed with the AVERAGE cost of other products in the same Category (AVERAGEIF).
A107: - Stock: 3 missing values imputed with the AVERAGE stock of other products in the same Category, rounded to whole units.
A108: - Duplicate_Check: COUNTIF-based flag confirms no duplicate Product_ID records.

Sheet Cleaned_StoreTable
A1: Store_ID | B1: Store_Name | C1: Region | D1: City | E1: Store_Type | F1: Duplicate_Check
A2: =Raw_Store_dim!A2 -> STORE0 | B2: =TRIM(Raw_Store_dim!B2) -> Rivera-Warner | C2: =Raw_Store_dim!C2 -> East | D2: =TRIM(Raw_Store_dim!D2) -> Washingtonfurt | E2: =Raw_Store_dim!E2 -> Flagship | F2: =IF(COUNTIF($A$2:$A2,A2)>1,"Duplicate","Unique") -> Unique
A3: =Raw_Store_dim!A3 -> STORE1 | B3: =TRIM(Raw_Store_dim!B3) -> Martinez, Adkins and Johnson | C3: =Raw_Store_dim!C3 -> North | D3: =TRIM(Raw_Store_dim!D3) -> Danielmouth | E3: =Raw_Store_dim!E3 -> Flagship | F3: =IF(COUNTIF($A$2:$A3,A3)>1,"Duplicate","Unique") -> Unique
A4: =Raw_Store_dim!A4 -> STORE2 | B4: =TRIM(Raw_Store_dim!B4) -> Black-Horn | C4: =Raw_Store_dim!C4 -> South | D4: =TRIM(Raw_Store_dim!D4) -> North Nancyview | E4: =Raw_Store_dim!E4 -> Outlet | F4: =IF(COUNTIF($A$2:$A4,A4)>1,"Duplicate","Unique") -> Unique
A5: =Raw_Store_dim!A5 -> STORE3 | B5: =TRIM(Raw_Store_dim!B5) -> Johnson-Wright | C5: =Raw_Store_dim!C5 -> North | D5: =TRIM(Raw_Store_dim!D5) -> Hoodberg | E5: =Raw_Store_dim!E5 -> Outlet | F5: =IF(COUNTIF($A$2:$A5,A5)>1,"Duplicate","Unique") -> Unique
A6: =Raw_Store_dim!A6 -> STORE4 | B6: =TRIM(Raw_Store_dim!B6) -> Alexander Group | C6: =Raw_Store_dim!C6 -> South | D6: =TRIM(Raw_Store_dim!D6) -> Port Sharon | E6: =Raw_Store_dim!E6 -> Online | F6: =IF(COUNTIF($A$2:$A6,A6)>1,"Duplicate","Unique") -> Unique
A7: =Raw_Store_dim!A7 -> STORE5 | B7: =TRIM(Raw_Store_dim!B7) -> Gray Ltd | C7: =Raw_Store_dim!C7 -> North | D7: =TRIM(Raw_Store_dim!D7) -> New Michaelchester | E7: =Raw_Store_dim!E7 -> Outlet | F7: =IF(COUNTIF($A$2:$A7,A7)>1,"Duplicate","Unique") -> Unique
A8: =Raw_Store_dim!A8 -> STORE6 | B8: =TRIM(Raw_Store_dim!B8) -> Benson-Elliott | C8: =Raw_Store_dim!C8 -> East | D8: =TRIM(Raw_Store_dim!D8) -> Port Josephberg | E8: =Raw_Store_dim!E8 -> Online | F8: =IF(COUNTIF($A$2:$A8,A8)>1,"Duplicate","Unique") -> Unique
A9: =Raw_Store_dim!A9 -> STORE7 | B9: =TRIM(Raw_Store_dim!B9) -> Martinez-Mullins | C9: =Raw_Store_dim!C9 -> South | D9: =TRIM(Raw_Store_dim!D9) -> Williamsfurt | E9: =Raw_Store_dim!E9 -> Online | F9: =IF(COUNTIF($A$2:$A9,A9)>1,"Duplicate","Unique") -> Unique
A10: =Raw_Store_dim!A10 -> STORE8 | B10: =TRIM(Raw_Store_dim!B10) -> Bean, Jones and Park | C10: =Raw_Store_dim!C10 -> West | D10: =TRIM(Raw_Store_dim!D10) -> Thompsonborough | E10: =Raw_Store_dim!E10 -> Online | F10: =IF(COUNTIF($A$2:$A10,A10)>1,"Duplicate","Unique") -> Unique
A11: =Raw_Store_dim!A11 -> STORE9 | B11: =TRIM(Raw_Store_dim!B11) -> Moore, Padilla and Butler | C11: =Raw_Store_dim!C11 -> South | D11: =TRIM(Raw_Store_dim!D11) -> East Johnstad | E11: =Raw_Store_dim!E11 -> Flagship | F11: =IF(COUNTIF($A$2:$A11,A11)>1,"Duplicate","Unique") -> Unique
A12: =Raw_Store_dim!A12 -> STORE10 | B12: =TRIM(Raw_Store_dim!B12) -> Hill, Wagner and Ballard | C12: =Raw_Store_dim!C12 -> East | D12: =TRIM(Raw_Store_dim!D12) -> East Davidville | E12: =Raw_Store_dim!E12 -> Online | F12: =IF(COUNTIF($A$2:$A12,A12)>1,"Duplicate","Unique") -> Unique
A13: =Raw_Store_dim!A13 -> STORE11 | B13: =TRIM(Raw_Store_dim!B13) -> Aguirre-Keller | C13: =Raw_Store_dim!C13 -> South | D13: =TRIM(Raw_Store_dim!D13) -> Lake Michael | E13: =Raw_Store_dim!E13 -> Online | F13: =IF(COUNTIF($A$2:$A13,A13)>1,"Duplicate","Unique") -> Unique
... A21: =Raw_Store_dim!A21 -> STORE19 | B21: =TRIM(Raw_Store_dim!B21) -> Mann-Austin | C21: =Raw_Store_dim!C21 -> East | D21: =TRIM(Raw_Store_dim!D21) -> Vasquezborough | E21: =Raw_Store_dim!E21 -> Online | F21: =IF(COUNTIF($A$2:$A21,A21)>1,"Duplicate","Unique") -> Unique
A23: Cleaning notes / assumptions:
A24: - No missing values found in the Store dimension; Store_Name/City trimmed for consistency.
A25: - Duplicate_Check: COUNTIF-based flag confirms no duplicate Store_ID records.

Sheet Cleaned_SalesTable
A1: Sales_ID | B1: Order_Date | C1: Customer_ID | D1: Product_ID | E1: Store_ID | F1: Quantity | G1: Unit_Price | H1: Discount | I1: Payment_Type | J1: Total_Amount | K1: Duplicate_Check
A2: =Raw_SalesFact!A2 -> SALE0 | B2: =Raw_SalesFact!B2 -> 45480 | C2: =Raw_SalesFact!C2 -> CUST1409 | D2: =Raw_SalesFact!D2 -> PROD97 | E2: =Raw_SalesFact!E2 -> STORE3 | F2: =IF(Raw_SalesFact!F2="",ROUND(AVERAGE(Raw_SalesFact!$F$2:$F$2001),0),Raw_SalesFact!F2) -> 1 | G2: =IF(Raw_SalesFact!G2="",ROUND(AVERAGEIF(Raw_SalesFact!$D$2:$D$2001,D2,Raw_SalesFact!$G$2:$G$2001),2),Raw_SalesFact!G2) -> 218.04 | H2: =IF(Raw_SalesFact!H2="",0,Raw_SalesFact!H2) -> 0.09 | I2: =Raw_SalesFact!I2 -> Credit Card | J2: =IF(Raw_SalesFact!J2="",ROUND(F2*G2*(1-H2),2),Raw_SalesFact!J2) -> 198.4164 | K2: =IF(COUNTIF($A$2:$A2,A2)>1,"Duplicate","Unique") -> Unique
A3: =Raw_SalesFact!A3 -> SALE1 | B3: =Raw_SalesFact!B3 -> 45285 | C3: =Raw_SalesFact!C3 -> CUST1467 | D3: =Raw_SalesFact!D3 -> PROD74 | E3: =Raw_SalesFact!E3 -> STORE17 | F3: =IF(Raw_SalesFact!F3="",ROUND(AVERAGE(Raw_SalesFact!$F$2:$F$2001),0),Raw_SalesFact!F3) -> 3 | G3: =IF(Raw_SalesFact!G3="",ROUND(AVERAGEIF(Raw_SalesFact!$D$2:$D$2001,D3,Raw_SalesFact!$G$2:$G$2001),2),Raw_SalesFact!G3) -> 104.47 | H3: =IF(Raw_SalesFact!H3="",0,Raw_SalesFact!H3) -> 0.27 | I3: =Raw_SalesFact!I3 -> PayPal | J3: =IF(Raw_SalesFact!J3="",ROUND(F3*G3*(1-H3),2),Raw_SalesFact!J3) -> 228.7893 | K3: =IF(COUNTIF($A$2:$A3,A3)>1,"Duplicate","Unique") -> Unique
A4: =Raw_SalesFact!A4 -> SALE2 | B4: =Raw_SalesFact!B4 -> 45446 | C4: =Raw_SalesFact!C4 -> CUST1056 | D4: =Raw_SalesFact!D4 -> PROD49 | E4: =Raw_SalesFact!E4 -> STORE8 | F4: =IF(Raw_SalesFact!F4="",ROUND(AVERAGE(Raw_SalesFact!$F$2:$F$2001),0),Raw_SalesFact!F4) -> 4 | G4: =IF(Raw_SalesFact!G4="",ROUND(AVERAGEIF(Raw_SalesFact!$D$2:$D$2001,D4,Raw_SalesFact!$G$2:$G$2001),2),Raw_SalesFact!G4) -> 914.05 | H4: =IF(Raw_SalesFact!H4="",0,Raw_SalesFact!H4) -> 0.25 | I4: =Raw_SalesFact!I4 -> Credit Card | J4: =IF(Raw_SalesFact!J4="",ROUND(F4*G4*(1-H4),2),Raw_SalesFact!J4) -> 2742.15 | K4: =IF(COUNTIF($A$2:$A4,A4)>1,"Duplicate","Unique") -> Unique
A5: =Raw_SalesFact!A5 -> SALE3 | B5: =Raw_SalesFact!B5 -> 45259 | C5: =Raw_SalesFact!C5 -> CUST1346 | D5: =Raw_SalesFact!D5 -> PROD76 | E5: =Raw_SalesFact!E5 -> STORE8 | F5: =IF(Raw_SalesFact!F5="",ROUND(AVERAGE(Raw_SalesFact!$F$2:$F$2001),0),Raw_SalesFact!F5) -> 1 | G5: =IF(Raw_SalesFact!G5="",ROUND(AVERAGEIF(Raw_SalesFact!$D$2:$D$2001,D5,Raw_SalesFact!$G$2:$G$2001),2),Raw_SalesFact!G5) -> 921.51 | H5: =IF(Raw_SalesFact!H5="",0,Raw_SalesFact!H5) -> 0.16 | I5: =Raw_SalesFact!I5 -> COD | J5: =IF(Raw_SalesFact!J5="",ROUND(F5*G5*(1-H5),2),Raw_SalesFact!J5) -> 774.0684 | K5: =IF(COUNTIF($A$2:$A5,A5)>1,"Duplicate","Unique") -> Unique
A6: =Raw_SalesFact!A6 -> SALE4 | B6: =Raw_SalesFact!B6 -> 45297 | C6: =Raw_SalesFact!C6 -> CUST1493 | D6: =Raw_SalesFact!D6 -> PROD59 | E6: =Raw_SalesFact!E6 -> STORE5 | F6: =IF(Raw_SalesFact!F6="",ROUND(AVERAGE(Raw_SalesFact!$F$2:$F$2001),0),Raw_SalesFact!F6) -> 3 | G6: =IF(Raw_SalesFact!G6="",ROUND(AVERAGEIF(Raw_SalesFact!$D$2:$D$2001,D6,Raw_SalesFact!$G$2:$G$2001),2),Raw_SalesFact!G6) -> 745.3 | H6: =IF(Raw_SalesFact!H6="",0,Raw_SalesFact!H6) -> 0.18 | I6: =Raw_SalesFact!I6 -> Credit Card | J6: =IF(Raw_SalesFact!J6="",ROUND(F6*G6*(1-H6),2),Raw_SalesFact!J6) -> 1833.438 | K6: =IF(COUNTIF($A$2:$A6,A6)>1,"Duplicate","Unique") -> Unique
A7: =Raw_SalesFact!A7 -> SALE5 | B7: =Raw_SalesFact!B7 -> 45499 | C7: =Raw_SalesFact!C7 -> CUST1116 | D7: =Raw_SalesFact!D7 -> PROD15 | E7: =Raw_SalesFact!E7 -> STORE7 | F7: =IF(Raw_SalesFact!F7="",ROUND(AVERAGE(Raw_SalesFact!$F$2:$F$2001),0),Raw_SalesFact!F7) -> 3 | G7: =IF(Raw_SalesFact!G7="",ROUND(AVERAGEIF(Raw_SalesFact!$D$2:$D$2001,D7,Raw_SalesFact!$G$2:$G$2001),2),Raw_SalesFact!G7) -> 147.01 | H7: =IF(Raw_SalesFact!H7="",0,Raw_SalesFact!H7) -> 0.19 | I7: =Raw_SalesFact!I7 -> COD | J7: =IF(Raw_SalesFact!J7="",ROUND(F7*G7*(1-H7),2),Raw_SalesFact!J7) -> 357.2343 | K7: =IF(COUNTIF($A$2:$A7,A7)>1,"Duplicate","Unique") -> Unique
A8: =Raw_SalesFact!A8 -> SALE6 | B8: =Raw_SalesFact!B8 -> 45850 | C8: =Raw_SalesFact!C8 -> CUST1016 | D8: =Raw_SalesFact!D8 -> PROD56 | E8: =Raw_SalesFact!E8 -> STORE4 | F8: =IF(Raw_SalesFact!F8="",ROUND(AVERAGE(Raw_SalesFact!$F$2:$F$2001),0),Raw_SalesFact!F8) -> 2 | G8: =IF(Raw_SalesFact!G8="",ROUND(AVERAGEIF(Raw_SalesFact!$D$2:$D$2001,D8,Raw_SalesFact!$G$2:$G$2001),2),Raw_SalesFact!G8) -> 785.31 | H8: =IF(Raw_SalesFact!H8="",0,Raw_SalesFact!H8) -> 0.15 | I8: =Raw_SalesFact!I8 -> PayPal | J8: =IF(Raw_SalesFact!J8="",ROUND(F8*G8*(1-H8),2),Raw_SalesFact!J8) -> 1335.027 | K8: =IF(COUNTIF($A$2:$A8,A8)>1,"Duplicate","Unique") -> Unique
A9: =Raw_SalesFact!A9 -> SALE7 | B9: =Raw_SalesFact!B9 -> 45248 | C9: =Raw_SalesFact!C9 -> CUST1152 | D9: =Raw_SalesFact!D9 -> PROD70 | E9: =Raw_SalesFact!E9 -> STORE8 | F9: =IF(Raw_SalesFact!F9="",ROUND(AVERAGE(Raw_SalesFact!$F$2:$F$2001),0),Raw_SalesFact!F9) -> 4 | G9: =IF(Raw_SalesFact!G9="",ROUND(AVERAGEIF(Raw_SalesFact!$D$2:$D$2001,D9,Raw_SalesFact!$G$2:$G$2001),2),Raw_SalesFact!G9) -> 342.39 | H9: =IF(Raw_SalesFact!H9="",0,Raw_SalesFact!H9) -> 0.23 | I9: =Raw_SalesFact!I9 -> PayPal | J9: =IF(Raw_SalesFact!J9="",ROUND(F9*G9*(1-H9),2),Raw_SalesFact!J9) -> 1054.5612 | K9: =IF(COUNTIF($A$2:$A9,A9)>1,"Duplicate","Unique") -> Unique
A10: =Raw_SalesFact!A10 -> SALE8 | B10: =Raw_SalesFact!B10 -> 45781 | C10: =Raw_SalesFact!C10 -> CUST1187 | D10: =Raw_SalesFact!D10 -> PROD99 | E10: =Raw_SalesFact!E10 -> STORE5 | F10: =IF(Raw_SalesFact!F10="",ROUND(AVERAGE(Raw_SalesFact!$F$2:$F$2001),0),Raw_SalesFact!F10) -> 2 | G10: =IF(Raw_SalesFact!G10="",ROUND(AVERAGEIF(Raw_SalesFact!$D$2:$D$2001,D10,Raw_SalesFact!$G$2:$G$2001),2),Raw_SalesFact!G10) -> 448.25 | H10: =IF(Raw_SalesFact!H10="",0,Raw_SalesFact!H10) -> 0.07 | I10: =Raw_SalesFact!I10 -> PayPal | J10: =IF(Raw_SalesFact!J10="",ROUND(F10*G10*(1-H10),2),Raw_SalesFact!J10) -> 1250.6175 | K10: =IF(COUNTIF($A$2:$A10,A10)>1,"Duplicate","Unique") -> Unique
A11: =Raw_SalesFact!A11 -> SALE9 | B11: =Raw_SalesFact!B11 -> 45869 | C11: =Raw_SalesFact!C11 -> CUST1464 | D11: =Raw_SalesFact!D11 -> PROD33 | E11: =Raw_SalesFact!E11 -> STORE0 | F11: =IF(Raw_SalesFact!F11="",ROUND(AVERAGE(Raw_SalesFact!$F$2:$F$2001),0),Raw_SalesFact!F11) -> 2 | G11: =IF(Raw_SalesFact!G11="",ROUND(AVERAGEIF(Raw_SalesFact!$D$2:$D$2001,D11,Raw_SalesFact!$G$2:$G$2001),2),Raw_SalesFact!G11) -> 873.17 | H11: =IF(Raw_SalesFact!H11="",0,Raw_SalesFact!H11) -> 0.23 | I11: =Raw_SalesFact!I11 -> PayPal | J11: =IF(Raw_SalesFact!J11="",ROUND(F11*G11*(1-H11),2),Raw_SalesFact!J11) -> 1344.6818 | K11: =IF(COUNTIF($A$2:$A11,A11)>1,"Duplicate","Unique") -> Unique
A12: =Raw_SalesFact!A12 -> SALE10 | B12: =Raw_SalesFact!B12 -> 45335 | C12: =Raw_SalesFact!C12 -> CUST1065 | D12: =Raw_SalesFact!D12 -> PROD24 | E12: =Raw_SalesFact!E12 -> STORE14 | F12: =IF(Raw_SalesFact!F12="",ROUND(AVERAGE(Raw_SalesFact!$F$2:$F$2001),0),Raw_SalesFact!F12) -> 1 | G12: =IF(Raw_SalesFact!G12="",ROUND(AVERAGEIF(Raw_SalesFact!$D$2:$D$2001,D12,Raw_SalesFact!$G$2:$G$2001),2),Raw_SalesFact!G12) -> 278.63 | H12: =IF(Raw_SalesFact!H12="",0,Raw_SalesFact!H12) -> 0.07 | I12: =Raw_SalesFact!I12 -> Credit Card | J12: =IF(Raw_SalesFact!J12="",ROUND(F12*G12*(1-H12),2),Raw_SalesFact!J12) -> 259.1259 | K12: =IF(COUNTIF($A$2:$A12,A12)>1,"Duplicate","Unique") -> Unique
A13: =Raw_SalesFact!A13 -> SALE11 | B13: =Raw_SalesFact!B13 -> 45801 | C13: =Raw_SalesFact!C13 -> CUST1320 | D13: =Raw_SalesFact!D13 -> PROD39 | E13: =Raw_SalesFact!E13 -> STORE1 | F13: =IF(Raw_SalesFact!F13="",ROUND(AVERAGE(Raw_SalesFact!$F$2:$F$2001),0),Raw_SalesFact!F13) -> 4 | G13: =IF(Raw_SalesFact!G13="",ROUND(AVERAGEIF(Raw_SalesFact!$D$2:$D$2001,D13,Raw_SalesFact!$G$2:$G$2001),2),Raw_SalesFact!G13) -> 286.92 | H13: =IF(Raw_SalesFact!H13="",0,Raw_SalesFact!H13) -> 0.17 | I13: =Raw_SalesFact!I13 -> Credit Card | J13: =IF(Raw_SalesFact!J13="",ROUND(F13*G13*(1-H13),2),Raw_SalesFact!J13) -> 952.5744 | K13: =IF(COUNTIF($A$2:$A13,A13)>1,"Duplicate","Unique") -> Unique
... A2001: =Raw_SalesFact!A2001 -> SALE1999 | B2001: =Raw_SalesFact!B2001 -> 45267 | C2001: =Raw_SalesFact!C2001 -> CUST1023 | D2001: =Raw_SalesFact!D2001 -> PROD76 | E2001: =Raw_SalesFact!E2001 -> STORE19 | F2001: =IF(Raw_SalesFact!F2001="",ROUND(AVERAGE(Raw_SalesFact!$F$2:$F$2001),0),Raw_SalesFact!F2001) -> 3 | G2001: =IF(Raw_SalesFact!G2001="",ROUND(AVERAGEIF(Raw_SalesFact!$D$2:$D$2001,D2001,Raw_SalesFact!$G$2:$G$2001),2),Raw_SalesFact!G2001) -> 68.45 | H2001: =IF(Raw_SalesFact!H2001="",0,Raw_SalesFact!H2001) -> 0.17 | I2001: =Raw_SalesFact!I2001 -> PayPal | J2001: =IF(Raw_SalesFact!J2001="",ROUND(F2001*G2001*(1-H2001),2),Raw_SalesFact!J2001) -> 170.4405 | K2001: =IF(COUNTIF($A$2:$A2001,A2001)>1,"Duplicate","Unique") -> Unique
A2003: Cleaning notes / assumptions:
A2004: - Quantity: 5 missing values filled with the overall AVERAGE quantity across all orders (rounded).
A2005: - Unit_Price: 3 missing values filled with the AVERAGE selling price of the same Product_ID (AVERAGEIF).
A2006: - Discount: 4 missing values assumed to be 0% (no discount applied), shown as a percentage.
A2007: - Total_Amount: 4 missing values recomputed as Quantity x Unit_Price x (1-Discount) using the cleaned figures.
A2008: - Duplicate_Check: COUNTIF-based flag confirms no duplicate Sales_ID records.

Sheet Merged_Data
A1: Sales_ID | B1: Order_Date | C1: Order_Month | D1: Order_Year | E1: Customer_ID | F1: Customer_Name | G1: Customer_Age | H1: Loyalty_Level | I1: Customer_State | J1: Product_ID | K1: Product_Name | L1: Category | M1: Brand | N1: Unit_Cost | O1: Store_ID | P1: Store_Name | Q1: Region | R1: Store_Type | S1: Quantity | T1: Unit_Price | U1: Discount | V1: Payment_Type | W1: Total_Amount | X1: Total_Cost | Y1: Profit | Z1: Profit_Margin_% | AA1: Order_Size
A2: =Cleaned_SalesTable!A2 -> SALE0 | B2: =Cleaned_SalesTable!B2 -> 45480 | C2: =TEXT(B2,"mmm-yyyy") -> Jul-2024 | D2: =YEAR(B2) -> 2024 | E2: =Cleaned_SalesTable!C2 -> CUST1409 | F2: =VLOOKUP(E2,Cleaned_CustomerTable!$A:$H,2,FALSE()) -> Sarah Smith | G2: =VLOOKUP(E2,Cleaned_CustomerTable!$A:$H,3,FALSE()) -> 55 | H2: =VLOOKUP(E2,Cleaned_CustomerTable!$A:$H,8,FALSE()) -> Gold | I2: =VLOOKUP(E2,Cleaned_CustomerTable!$A:$H,6,FALSE()) -> Wyoming | J2: =Cleaned_SalesTable!D2 -> PROD97 | K2: =VLOOKUP(J2,Cleaned_ProductTable!$A:$F,2,FALSE()) -> Cricket Bat | L2: =VLOOKUP(J2,Cleaned_ProductTable!$A:$F,3,FALSE()) -> Sports | M2: =VLOOKUP(J2,Cleaned_ProductTable!$A:$F,4,FALSE()) -> Khan LLC | N2: =VLOOKUP(J2,Cleaned_ProductTable!$A:$F,5,FALSE()) -> 245.98 | O2: =Cleaned_SalesTable!E2 -> STORE3 | P2: =VLOOKUP(O2,Cleaned_StoreTable!$A:$F,2,FALSE()) -> Johnson-Wright | Q2: =VLOOKUP(O2,Cleaned_StoreTable!$A:$F,3,FALSE()) -> North | R2: =VLOOKUP(O2,Cleaned_StoreTable!$A:$F,5,FALSE()) -> Outlet | S2: =Cleaned_SalesTable!F2 -> 1 | T2: =Cleaned_SalesTable!G2 -> 218.04 | U2: =Cleaned_SalesTable!H2 -> 0.09 | V2: =Cleaned_SalesTable!I2 -> Credit Card | W2: =Cleaned_SalesTable!J2 -> 198.4164 | X2: =ROUND(N2*S2,2) -> 245.98 | Y2: =ROUND(W2-X2,2) -> -47.56 | Z2: =IFERROR(ROUND(Y2/W2,4),0) -> -0.2397 | AA2: =IF(W2>=AVERAGE($W$2:$W$2001),"High Value","Standard") -> Standard
A3: =Cleaned_SalesTable!A3 -> SALE1 | B3: =Cleaned_SalesTable!B3 -> 45285 | C3: =TEXT(B3,"mmm-yyyy") -> Dec-2023 | D3: =YEAR(B3) -> 2023 | E3: =Cleaned_SalesTable!C3 -> CUST1467 | F3: =VLOOKUP(E3,Cleaned_CustomerTable!$A:$H,2,FALSE()) -> Michael Foley | G3: =VLOOKUP(E3,Cleaned_CustomerTable!$A:$H,3,FALSE()) -> 63 | H3: =VLOOKUP(E3,Cleaned_CustomerTable!$A:$H,8,FALSE()) -> Gold | I3: =VLOOKUP(E3,Cleaned_CustomerTable!$A:$H,6,FALSE()) -> Vermont | J3: =Cleaned_SalesTable!D3 -> PROD74 | K3: =VLOOKUP(J3,Cleaned_ProductTable!$A:$F,2,FALSE()) -> Bluetooth Car Audio System | L3: =VLOOKUP(J3,Cleaned_ProductTable!$A:$F,3,FALSE()) -> Electronics | M3: =VLOOKUP(J3,Cleaned_ProductTable!$A:$F,4,FALSE()) -> Bruce-Bowen | N3: =VLOOKUP(J3,Cleaned_ProductTable!$A:$F,5,FALSE()) -> 403.71 | O3: =Cleaned_SalesTable!E3 -> STORE17 | P3: =VLOOKUP(O3,Cleaned_StoreTable!$A:$F,2,FALSE()) -> Holloway Ltd | Q3: =VLOOKUP(O3,Cleaned_StoreTable!$A:$F,3,FALSE()) -> North | R3: =VLOOKUP(O3,Cleaned_StoreTable!$A:$F,5,FALSE()) -> Flagship | S3: =Cleaned_SalesTable!F3 -> 3 | T3: =Cleaned_SalesTable!G3 -> 104.47 | U3: =Cleaned_SalesTable!H3 -> 0.27 | V3: =Cleaned_SalesTable!I3 -> PayPal | W3: =Cleaned_SalesTable!J3 -> 228.7893 | X3: =ROUND(N3*S3,2) -> 1211.13 | Y3: =ROUND(W3-X3,2) -> -982.34 | Z3: =IFERROR(ROUND(Y3/W3,4),0) -> -4.2936 | AA3: =IF(W3>=AVERAGE($W$2:$W$2001),"High Value","Standard") -> Standard
A4: =Cleaned_SalesTable!A4 -> SALE2 | B4: =Cleaned_SalesTable!B4 -> 45446 | C4: =TEXT(B4,"mmm-yyyy") -> Jun-2024 | D4: =YEAR(B4) -> 2024 | E4: =Cleaned_SalesTable!C4 -> CUST1056 | F4: =VLOOKUP(E4,Cleaned_CustomerTable!$A:$H,2,FALSE()) -> Christopher Sutton | G4: =VLOOKUP(E4,Cleaned_CustomerTable!$A:$H,3,FALSE()) -> 49 | H4: =VLOOKUP(E4,Cleaned_CustomerTable!$A:$H,8,FALSE()) -> Gold | I4: =VLOOKUP(E4,Cleaned_CustomerTable!$A:$H,6,FALSE()) -> Pennsylvania | J4: =Cleaned_SalesTable!D4 -> PROD49 | K4: =VLOOKUP(J4,Cleaned_ProductTable!$A:$F,2,FALSE()) -> Men's Roll-On Perfume | L4: =VLOOKUP(J4,Cleaned_ProductTable!$A:$F,3,FALSE()) -> Beauty | M4: =VLOOKUP(J4,Cleaned_ProductTable!$A:$F,4,FALSE()) -> Sullivan and Sons | N4: =VLOOKUP(J4,Cleaned_ProductTable!$A:$F,5,FALSE()) -> 43.29 | O4: =Cleaned_SalesTable!E4 -> STORE8 | P4: =VLOOKUP(O4,Cleaned_StoreTable!$A:$F,2,FALSE()) -> Bean, Jones and Park | Q4: =VLOOKUP(O4,Cleaned_StoreTable!$A:$F,3,FALSE()) -> West | R4: =VLOOKUP(O4,Cleaned_StoreTable!$A:$F,5,FALSE()) -> Online | S4: =Cleaned_SalesTable!F4 -> 4 | T4: =Cleaned_SalesTable!G4 -> 914.05 | U4: =Cleaned_SalesTable!H4 -> 0.25 | V4: =Cleaned_SalesTable!I4 -> Credit Card | W4: =Cleaned_SalesTable!J4 -> 2742.15 | X4: =ROUND(N4*S4,2) -> 173.16 | Y4: =ROUND(W4-X4,2) -> 2568.99 | Z4: =IFERROR(ROUND(Y4/W4,4),0) -> 0.9369 | AA4: =IF(W4>=AVERAGE($W$2:$W$2001),"High Value","Standard") -> High Value
A5: =Cleaned_SalesTable!A5 -> SALE3 | B5: =Cleaned_SalesTable!B5 -> 45259 | C5: =TEXT(B5,"mmm-yyyy") -> Nov-2023 | D5: =YEAR(B5) -> 2023 | E5: =Cleaned_SalesTable!C5 -> CUST1346 | F5: =VLOOKUP(E5,Cleaned_CustomerTable!$A:$H,2,FALSE()) -> John Jordan | G5: =VLOOKUP(E5,Cleaned_CustomerTable!$A:$H,3,FALSE()) -> 58 | H5: =VLOOKUP(E5,Cleaned_CustomerTable!$A:$H,8,FALSE()) -> Platinum | I5: =VLOOKUP(E5,Cleaned_CustomerTable!$A:$H,6,FALSE()) -> Tennessee | J5: =Cleaned_SalesTable!D5 -> PROD76 | K5: =VLOOKUP(J5,Cleaned_ProductTable!$A:$F,2,FALSE()) -> Wireless Mouse | L5: =VLOOKUP(J5,Cleaned_ProductTable!$A:$F,3,FALSE()) -> Electronics | M5: =VLOOKUP(J5,Cleaned_ProductTable!$A:$F,4,FALSE()) -> Larson Ltd | N5: =VLOOKUP(J5,Cleaned_ProductTable!$A:$F,5,FALSE()) -> 392.89 | O5: =Cleaned_SalesTable!E5 -> STORE8 | P5: =VLOOKUP(O5,Cleaned_StoreTable!$A:$F,2,FALSE()) -> Bean, Jones and Park | Q5: =VLOOKUP(O5,Cleaned_StoreTable!$A:$F,3,FALSE()) -> West | R5: =VLOOKUP(O5,Cleaned_StoreTable!$A:$F,5,FALSE()) -> Online | S5: =Cleaned_SalesTable!F5 -> 1 | T5: =Cleaned_SalesTable!G5 -> 921.51 | U5: =Cleaned_SalesTable!H5 -> 0.16 | V5: =Cleaned_SalesTable!I5 -> COD | W5: =Cleaned_SalesTable!J5 -> 774.0684 | X5: =ROUND(N5*S5,2) -> 392.89 | Y5: =ROUND(W5-X5,2) -> 381.18 | Z5: =IFERROR(ROUND(Y5/W5,4),0) -> 0.4924 | AA5: =IF(W5>=AVERAGE($W$2:$W$2001),"High Value","Standard") -> Standard
A6: =Cleaned_SalesTable!A6 -> SALE4 | B6: =Cleaned_SalesTable!B6 -> 45297 | C6: =TEXT(B6,"mmm-yyyy") -> Jan-2024 | D6: =YEAR(B6) -> 2024 | E6: =Cleaned_SalesTable!C6 -> CUST1493 | F6: =VLOOKUP(E6,Cleaned_CustomerTable!$A:$H,2,FALSE()) -> Amanda Powell | G6: =VLOOKUP(E6,Cleaned_CustomerTable!$A:$H,3,FALSE()) -> 28 | H6: =VLOOKUP(E6,Cleaned_CustomerTable!$A:$H,8,FALSE()) -> Silver | I6: =VLOOKUP(E6,Cleaned_CustomerTable!$A:$H,6,FALSE()) -> Alabama | J6: =Cleaned_SalesTable!D6 -> PROD59 | K6: =VLOOKUP(J6,Cleaned_ProductTable!$A:$F,2,FALSE()) -> Men's Hair Styling Gel | L6: =VLOOKUP(J6,Cleaned_ProductTable!$A:$F,3,FALSE()) -> Beauty | M6: =VLOOKUP(J6,Cleaned_ProductTable!$A:$F,4,FALSE()) -> Cline-Mccarthy | N6: =VLOOKUP(J6,Cleaned_ProductTable!$A:$F,5,FALSE()) -> 17.31 | O6: =Cleaned_SalesTable!E6 -> STORE5 | P6: =VLOOKUP(O6,Cleaned_StoreTable!$A:$F,2,FALSE()) -> Gray Ltd | Q6: =VLOOKUP(O6,Cleaned_StoreTable!$A:$F,3,FALSE()) -> North | R6: =VLOOKUP(O6,Cleaned_StoreTable!$A:$F,5,FALSE()) -> Outlet | S6: =Cleaned_SalesTable!F6 -> 3 | T6: =Cleaned_SalesTable!G6 -> 745.3 | U6: =Cleaned_SalesTable!H6 -> 0.18 | V6: =Cleaned_SalesTable!I6 -> Credit Card | W6: =Cleaned_SalesTable!J6 -> 1833.438 | X6: =ROUND(N6*S6,2) -> 51.93 | Y6: =ROUND(W6-X6,2) -> 1781.51 | Z6: =IFERROR(ROUND(Y6/W6,4),0) -> 0.9717 | AA6: =IF(W6>=AVERAGE($W$2:$W$2001),"High Value","Standard") -> High Value
A7: =Cleaned_SalesTable!A7 -> SALE5 | B7: =Cleaned_SalesTable!B7 -> 45499 | C7: =TEXT(B7,"mmm-yyyy") -> Jul-2024 | D7: =YEAR(B7) -> 2024 | E7: =Cleaned_SalesTable!C7 -> CUST1116 | F7: =VLOOKUP(E7,Cleaned_CustomerTable!$A:$H,2,FALSE()) -> Anthony Phillips | G7: =VLOOKUP(E7,Cleaned_CustomerTable!$A:$H,3,FALSE()) -> 18 | H7: =VLOOKUP(E7,Cleaned_CustomerTable!$A:$H,8,FALSE()) -> Platinum | I7: =VLOOKUP(E7,Cleaned_CustomerTable!$A:$H,6,FALSE()) -> Rhode Island | J7: =Cleaned_SalesTable!D7 -> PROD15 | K7: =VLOOKUP(J7,Cleaned_ProductTable!$A:$F,2,FALSE()) -> 4K Home Projector | L7: =VLOOKUP(J7,Cleaned_ProductTable!$A:$F,3,FALSE()) -> Electronics | M7: =VLOOKUP(J7,Cleaned_ProductTable!$A:$F,4,FALSE()) -> Thomas LLC | N7: =VLOOKUP(J7,Cleaned_ProductTable!$A:$F,5,FALSE()) -> 465.34 | O7: =Cleaned_SalesTable!E7 -> STORE7 | P7: =VLOOKUP(O7,Cleaned_StoreTable!$A:$F,2,FALSE()) -> Martinez-Mullins | Q7: =VLOOKUP(O7,Cleaned_StoreTable!$A:$F,3,FALSE()) -> South | R7: =VLOOKUP(O7,Cleaned_StoreTable!$A:$F,5,FALSE()) -> Online | S7: =Cleaned_SalesTable!F7 -> 3 | T7: =Cleaned_SalesTable!G7 -> 147.01 | U7: =Cleaned_SalesTable!H7 -> 0.19 | V7: =Cleaned_SalesTable!I7 -> COD | W7: =Cleaned_SalesTable!J7 -> 357.2343 | X7: =ROUND(N7*S7,2) -> 1396.02 | Y7: =ROUND(W7-X7,2) -> -1038.79 | Z7: =IFERROR(ROUND(Y7/W7,4),0) -> -2.9079 | AA7: =IF(W7>=AVERAGE($W$2:$W$2001),"High Value","Standard") -> Standard
A8: =Cleaned_SalesTable!A8 -> SALE6 | B8: =Cleaned_SalesTable!B8 -> 45850 | C8: =TEXT(B8,"mmm-yyyy") -> Jul-2025 | D8: =YEAR(B8) -> 2025 | E8: =Cleaned_SalesTable!C8 -> CUST1016 | F8: =VLOOKUP(E8,Cleaned_CustomerTable!$A:$H,2,FALSE()) -> John Scott | G8: =VLOOKUP(E8,Cleaned_CustomerTable!$A:$H,3,FALSE()) -> 24 | H8: =VLOOKUP(E8,Cleaned_CustomerTable!$A:$H,8,FALSE()) -> Bronze | I8: =VLOOKUP(E8,Cleaned_CustomerTable!$A:$H,6,FALSE()) -> Pennsylvania | J8: =Cleaned_SalesTable!D8 -> PROD56 | K8: =VLOOKUP(J8,Cleaned_ProductTable!$A:$F,2,FALSE()) -> Premium Blanket Throw | L8: =VLOOKUP(J8,Cleaned_ProductTable!$A:$F,3,FALSE()) -> Home | M8: =VLOOKUP(J8,Cleaned_ProductTable!$A:$F,4,FALSE()) -> Hernandez, Kennedy and Porter | N8: =VLOOKUP(J8,Cleaned_ProductTable!$A:$F,5,FALSE()) -> 461.47 | O8: =Cleaned_SalesTable!E8 -> STORE4 | P8: =VLOOKUP(O8,Cleaned_StoreTable!$A:$F,2,FALSE()) -> Alexander Group | Q8: =VLOOKUP(O8,Cleaned_StoreTable!$A:$F,3,FALSE()) -> South | R8: =VLOOKUP(O8,Cleaned_StoreTable!$A:$F,5,FALSE()) -> Online | S8: =Cleaned_SalesTable!F8 -> 2 | T8: =Cleaned_SalesTable!G8 -> 785.31 | U8: =Cleaned_SalesTable!H8 -> 0.15 | V8: =Cleaned_SalesTable!I8 -> PayPal | W8: =Cleaned_SalesTable!J8 -> 1335.027 | X8: =ROUND(N8*S8,2) -> 922.94 | Y8: =ROUND(W8-X8,2) -> 412.09 | Z8: =IFERROR(ROUND(Y8/W8,4),0) -> 0.3087 | AA8: =IF(W8>=AVERAGE($W$2:$W$2001),"High Value","Standard") -> High Value
A9: =Cleaned_SalesTable!A9 -> SALE7 | B9: =Cleaned_SalesTable!B9 -> 45248 | C9: =TEXT(B9,"mmm-yyyy") -> Nov-2023 | D9: =YEAR(B9) -> 2023 | E9: =Cleaned_SalesTable!C9 -> CUST1152 | F9: =VLOOKUP(E9,Cleaned_CustomerTable!$A:$H,2,FALSE()) -> Patrick Roberts | G9: =VLOOKUP(E9,Cleaned_CustomerTable!$A:$H,3,FALSE()) -> 41 | H9: =VLOOKUP(E9,Cleaned_CustomerTable!$A:$H,8,FALSE()) -> Platinum | I9: =VLOOKUP(E9,Cleaned_CustomerTable!$A:$H,6,FALSE()) -> Missouri | J9: =Cleaned_SalesTable!D9 -> PROD70 | K9: =VLOOKUP(J9,Cleaned_ProductTable!$A:$F,2,FALSE()) -> Kitchen Storage Rack | L9: =VLOOKUP(J9,Cleaned_ProductTable!$A:$F,3,FALSE()) -> Home | M9: =VLOOKUP(J9,Cleaned_ProductTable!$A:$F,4,FALSE()) -> Duran Group | N9: =VLOOKUP(J9,Cleaned_ProductTable!$A:$F,5,FALSE()) -> 138.05 | O9: =Cleaned_SalesTable!E9 -> STORE8 | P9: =VLOOKUP(O9,Cleaned_StoreTable!$A:$F,2,FALSE()) -> Bean, Jones and Park | Q9: =VLOOKUP(O9,Cleaned_StoreTable!$A:$F,3,FALSE()) -> West | R9: =VLOOKUP(O9,Cleaned_StoreTable!$A:$F,5,FALSE()) -> Online | S9: =Cleaned_SalesTable!F9 -> 4 | T9: =Cleaned_SalesTable!G9 -> 342.39 | U9: =Cleaned_SalesTable!H9 -> 0.23 | V9: =Cleaned_SalesTable!I9 -> PayPal | W9: =Cleaned_SalesTable!J9 -> 1054.5612 | X9: =ROUND(N9*S9,2) -> 552.2 | Y9: =ROUND(W9-X9,2) -> 502.36 | Z9: =IFERROR(ROUND(Y9/W9,4),0) -> 0.4764 | AA9: =IF(W9>=AVERAGE($W$2:$W$2001),"High Value","Standard") -> Standard
A10: =Cleaned_SalesTable!A10 -> SALE8 | B10: =Cleaned_SalesTable!B10 -> 45781 | C10: =TEXT(B10,"mmm-yyyy") -> May-2025 | D10: =YEAR(B10) -> 2025 | E10: =Cleaned_SalesTable!C10 -> CUST1187 | F10: =VLOOKUP(E10,Cleaned_CustomerTable!$A:$H,2,FALSE()) -> Dr. Suzanne Bullock | G10: =VLOOKUP(E10,Cleaned_CustomerTable!$A:$H,3,FALSE()) -> 60 | H10: =VLOOKUP(E10,Cleaned_CustomerTable!$A:$H,8,FALSE()) -> Platinum | I10: =VLOOKUP(E10,Cleaned_CustomerTable!$A:$H,6,FALSE()) -> Alabama | J10: =Cleaned_SalesTable!D10 -> PROD99 | K10: =VLOOKUP(J10,Cleaned_ProductTable!$A:$F,2,FALSE()) -> Stainless Steel Cookware Set | L10: =VLOOKUP(J10,Cleaned_ProductTable!$A:$F,3,FALSE()) -> Home | M10: =VLOOKUP(J10,Cleaned_ProductTable!$A:$F,4,FALSE()) -> Campbell Ltd | N10: =VLOOKUP(J10,Cleaned_ProductTable!$A:$F,5,FALSE()) -> 201.41 | O10: =Cleaned_SalesTable!E10 -> STORE5 | P10: =VLOOKUP(O10,Cleaned_StoreTable!$A:$F,2,FALSE()) -> Gray Ltd | Q10: =VLOOKUP(O10,Cleaned_StoreTable!$A:$F,3,FALSE()) -> North | R10: =VLOOKUP(O10,Cleaned_StoreTable!$A:$F,5,FALSE()) -> Outlet | S10: =Cleaned_SalesTable!F10 -> 2 | T10: =Cleaned_SalesTable!G10 -> 448.25 | U10: =Cleaned_SalesTable!H10 -> 0.07 | V10: =Cleaned_SalesTable!I10 -> PayPal | W10: =Cleaned_SalesTable!J10 -> 1250.6175 | X10: =ROUND(N10*S10,2) -> 402.82 | Y10: =ROUND(W10-X10,2) -> 847.8 | Z10: =IFERROR(ROUND(Y10/W10,4),0) -> 0.6779 | AA10: =IF(W10>=AVERAGE($W$2:$W$2001),"High Value","Standard") -> High Value
A11: =Cleaned_SalesTable!A11 -> SALE9 | B11: =Cleaned_SalesTable!B11 -> 45869 | C11: =TEXT(B11,"mmm-yyyy") -> Jul-2025 | D11: =YEAR(B11) -> 2025 | E11: =Cleaned_SalesTable!C11 -> CUST1464 | F11: =VLOOKUP(E11,Cleaned_CustomerTable!$A:$H,2,FALSE()) -> David Pierce | G11: =VLOOKUP(E11,Cleaned_CustomerTable!$A:$H,3,FALSE()) -> 45 | H11: =VLOOKUP(E11,Cleaned_CustomerTable!$A:$H,8,FALSE()) -> Platinum | I11: =VLOOKUP(E11,Cleaned_CustomerTable!$A:$H,6,FALSE()) -> Washington | J11: =Cleaned_SalesTable!D11 -> PROD33 | K11: =VLOOKUP(J11,Cleaned_ProductTable!$A:$F,2,FALSE()) -> Modern Wall Clock | L11: =VLOOKUP(J11,Cleaned_ProductTable!$A:$F,3,FALSE()) -> Home | M11: =VLOOKUP(J11,Cleaned_ProductTable!$A:$F,4,FALSE()) -> Weiss-Watson | N11: =VLOOKUP(J11,Cleaned_ProductTable!$A:$F,5,FALSE()) -> 179.77 | O11: =Cleaned_SalesTable!E11 -> STORE0 | P11: =VLOOKUP(O11,Cleaned_StoreTable!$A:$F,2,FALSE()) -> Rivera-Warner | Q11: =VLOOKUP(O11,Cleaned_StoreTable!$A:$F,3,FALSE()) -> East | R11: =VLOOKUP(O11,Cleaned_StoreTable!$A:$F,5,FALSE()) -> Flagship | S11: =Cleaned_SalesTable!F11 -> 2 | T11: =Cleaned_SalesTable!G11 -> 873.17 | U11: =Cleaned_SalesTable!H11 -> 0.23 | V11: =Cleaned_SalesTable!I11 -> PayPal | W11: =Cleaned_SalesTable!J11 -> 1344.6818 | X11: =ROUND(N11*S11,2) -> 359.54 | Y11: =ROUND(W11-X11,2) -> 985.14 | Z11: =IFERROR(ROUND(Y11/W11,4),0) -> 0.7326 | AA11: =IF(W11>=AVERAGE($W$2:$W$2001),"High Value","Standard") -> High Value
